# エラー処理と例外管理

## 概要

信頼性の高いシステムにとって、適切なエラー処理と例外管理は不可欠です。このドキュメントでは、LangGraph Slide Generatorシステムにおけるエラー処理の戦略、例外階層、エラー回復メカニズムについて説明します。

## 例外階層

システム内で発生するエラーを整理し、適切に処理するための例外階層：

```
SlideGeneratorError
│
├── ImageProcessingError
│   ├── ImagePreprocessingError
│   ├── OCRError
│   └── StructureAnalysisError
│
├── LLMProcessingError
│   ├── LLMConnectionError
│   ├── LLMResponseError
│   └── ContentAnalysisError
│
├── HTMLGenerationError
│   ├── TemplateRenderingError
│   ├── StyleProcessingError
│   └── MathRenderingError
│
└── APIError
    ├── AuthenticationError
    ├── ValidationError
    └── ResourceNotFoundError
```

この階層構造により、以下のメリットが得られます：

- エラーの種類に基づく細粒度の例外処理
- エラー原因の明確な分類
- 異なるコンポーネント間での一貫したエラー処理

## 例外定義

主要な例外クラスの定義例：

```python
# src/exceptions.py
class SlideGeneratorError(Exception):
    """アプリケーション固有の基底例外クラス。"""
    
    def __init__(self, message, details=None):
        super().__init__(message)
        self.details = details or {}

class ImageProcessingError(SlideGeneratorError):
    """画像処理中のエラー。"""
    pass

class OCRError(ImageProcessingError):
    """OCR処理中のエラー。"""
    
    def __init__(self, message, image_id=None, details=None):
        super().__init__(message, details)
        self.image_id = image_id

class LLMProcessingError(SlideGeneratorError):
    """LLM処理中のエラー。"""
    pass

class HTMLGenerationError(SlideGeneratorError):
    """HTML生成中のエラー。"""
    pass

class APIError(SlideGeneratorError):
    """API関連のエラー。"""
    
    def __init__(self, message, status_code=500, details=None):
        super().__init__(message, details)
        self.status_code = status_code
```

## エラー処理戦略

### 例外のキャッチとロギング

適切なレベルでの例外処理：

1. **ローカル処理**：可能な限り処理を続行できるエラーはローカルで処理
2. **上位への伝播**：回復不能なエラーは適切な情報とともに上位レイヤーに伝播
3. **詳細なロギング**：トラブルシューティングに役立つ情報を含むログ記録

例：

```python
def process_image(image_data):
    try:
        # 画像処理ロジック
        preprocessed = preprocess_image(image_data)
        text_blocks = extract_text(preprocessed)
        return analyze_structure(text_blocks)
    
    except ImagePreprocessingError as e:
        # 前処理エラーのログ記録と回復試行
        logger.warning(f"Image preprocessing failed: {str(e)}")
        # フォールバック処理または再試行
        
    except OCRError as e:
        # OCRエラーのログ記録
        logger.error(f"OCR failed for image: {str(e)}")
        # 部分的な結果の返却または例外の再発生
        
    except Exception as e:
        # 予期しないエラーの詳細なログ記録
        logger.exception(f"Unexpected error in image processing: {str(e)}")
        # 適切な例外への変換と再発生
        raise ImageProcessingError(f"Failed to process image: {str(e)}") from e
```

### コンテキストマネージャによるエラー処理

コード重複を減らすためのコンテキストマネージャの活用：

```python
from contextlib import contextmanager

@contextmanager
def error_handling(error_type, error_message):
    """エラーハンドリングとログ記録のためのコンテキストマネージャ。"""
    try:
        yield
    except Exception as e:
        logger.error(
            f"{error_message}: {str(e)}\n{traceback.format_exc()}"
        )
        raise error_type(f"{error_message}: {str(e)}") from e

# 使用例
def process_content(content_data):
    with error_handling(ContentAnalysisError, "Failed to analyze content"):
        # コンテンツ処理ロジック
        return analyze_content(content_data)
```

## リトライメカニズム

一時的なエラーからの回復のためのリトライ戦略：

### 指数バックオフリトライ

```python
import time
from functools import wraps

def retry(max_attempts=3, initial_delay=1, backoff=2, exceptions=(Exception,)):
    """指定した例外が発生した場合に関数を再試行するデコレータ。"""
    def decorator(func):
        @wraps(func)
        def wrapper(*args, **kwargs):
            attempt = 0
            current_delay = initial_delay
            
            while attempt < max_attempts:
                try:
                    return func(*args, **kwargs)
                except exceptions as e:
                    attempt += 1
                    if attempt >= max_attempts:
                        raise
                    
                    logger.warning(
                        f"Retry {attempt}/{max_attempts} for {func.__name__} "
                        f"after error: {str(e)}. Waiting {current_delay}s."
                    )
                    
                    time.sleep(current_delay)
                    current_delay *= backoff
                    
        return wrapper
    return decorator

# 使用例
@retry(max_attempts=5, exceptions=(LLMConnectionError, TimeoutError))
def call_llm_api(prompt, model="gpt-4"):
    # LLM API呼び出しロジック
    return llm_client.generate(prompt, model=model)
```

### サーキットブレーカー

繰り返しのエラーが発生した場合にサービスを一時的に無効化するサーキットブレーカーパターン：

```python
class CircuitBreaker:
    """サーキットブレーカーパターンの実装。"""
    
    def __init__(self, failure_threshold=5, recovery_timeout=60):
        self.failure_threshold = failure_threshold
        self.recovery_timeout = recovery_timeout
        self.failure_count = 0
        self.last_failure_time = 0
        self.state = "CLOSED"  # CLOSED, OPEN, HALF-OPEN
    
    def execute(self, func, *args, **kwargs):
        """関数を実行し、エラー発生時にサーキットを開く。"""
        current_time = time.time()
        
        # OPEN状態でリカバリータイムアウト経過後はHALF-OPEN状態に移行
        if self.state == "OPEN" and current_time - self.last_failure_time > self.recovery_timeout:
            self.state = "HALF-OPEN"
            logger.info("Circuit breaker transitioned to HALF-OPEN state")
        
        # OPEN状態ではエラーをスローして処理をスキップ
        if self.state == "OPEN":
            raise CircuitBreakerOpenError("Circuit breaker is OPEN")
        
        try:
            result = func(*args, **kwargs)
            
            # HALF-OPEN状態で成功したらCLOSED状態に戻す
            if self.state == "HALF-OPEN":
                self.reset()
                logger.info("Circuit breaker transitioned to CLOSED state")
                
            return result
            
        except Exception as e:
            self.failure_count += 1
            self.last_failure_time = current_time
            
            # 失敗閾値に達したらOPEN状態に移行
            if (self.state == "CLOSED" and self.failure_count >= self.failure_threshold) or self.state == "HALF-OPEN":
                self.state = "OPEN"
                logger.warning(f"Circuit breaker transitioned to OPEN state after {self.failure_count} failures")
            
            raise
    
    def reset(self):
        """サーキットブレーカーをリセットしてCLOSED状態に戻す。"""
        self.failure_count = 0
        self.state = "CLOSED"
```

## LangGraphでのエラー処理

LangGraphワークフロー内でのエラー処理戦略：

### エラー処理ノード

```python
def handle_error_node(state: ProcessingState) -> Dict[str, Any]:
    """ワークフロー内のエラー処理を行うノード。"""
    # エラーのログ記録
    for error in state.errors:
        logger.error(f"Workflow error: {error}")
    
    # エラータイプに基づく対応の判断
    if any("OCR" in error for error in state.errors):
        # OCRエラーに対する回復戦略
        recovery_strategy = "alternative_ocr"
    elif any("LLM" in error for error in state.errors):
        # LLMエラーに対する回復戦略
        recovery_strategy = "simplified_analysis"
    else:
        # その他のエラーに対するデフォルト戦略
        recovery_strategy = "default"
    
    # 回復戦略の適用結果を返却
    return {
        "status": ProcessingStatus.FAILED if not apply_recovery(state, recovery_strategy) else ProcessingStatus.PROCESSING,
        "recovery_attempted": True,
        "recovery_strategy": recovery_strategy
    }
```

### 条件付きエッジによるエラーフロー制御

```python
# グラフ定義内
graph.add_conditional_edges(
    "preprocess_images",
    lambda state: "handle_error" if state.errors else "extract_text"
)

graph.add_conditional_edges(
    "handle_error",
    lambda state: "end" if state.status == ProcessingStatus.FAILED else "retry_processing"
)
```

## APIエラーレスポンス

APIからのエラーレスポンスの標準化：

```python
from fastapi import HTTPException
from fastapi.responses import JSONResponse
from fastapi.exceptions import RequestValidationError
from starlette.requests import Request
from starlette.status import HTTP_422_UNPROCESSABLE_ENTITY

# エラーレスポンスモデル
class ErrorResponse(BaseModel):
    status: str = "error"
    error: Dict[str, Any]

# FastAPIのエラーハンドラ
@app.exception_handler(RequestValidationError)
async def validation_exception_handler(request: Request, exc: RequestValidationError):
    """バリデーションエラーを標準形式でハンドリング。"""
    return JSONResponse(
        status_code=HTTP_422_UNPROCESSABLE_ENTITY,
        content=ErrorResponse(
            error={
                "code": "validation_error",
                "message": "Invalid request parameters",
                "details": exc.errors()
            }
        ).dict()
    )

@app.exception_handler(APIError)
async def api_error_handler(request: Request, exc: APIError):
    """APIエラーを標準形式でハンドリング。"""
    return JSONResponse(
        status_code=exc.status_code,
        content=ErrorResponse(
            error={
                "code": exc.__class__.__name__.lower(),
                "message": str(exc),
                "details": exc.details
            }
        ).dict()
    )

@app.exception_handler(Exception)
async def general_exception_handler(request: Request, exc: Exception):
    """予期しない例外を標準形式でハンドリング。"""
    # エラーのログ記録
    logger.exception(f"Unhandled exception: {str(exc)}")
    
    return JSONResponse(
        status_code=500,
        content=ErrorResponse(
            error={
                "code": "internal_error",
                "message": "An unexpected error occurred",
                "details": {"error": str(exc)} if DEBUG else {}
            }
        ).dict()
    )
```

## エラー報告と監視

### エラーメトリクス収集

エラーの傾向を分析するためのメトリクス収集：

```python
class ErrorMetrics:
    """エラーメトリクスの収集と分析。"""
    
    def __init__(self):
        self.error_counts = defaultdict(int)
        self.error_rates = defaultdict(list)
        self.last_errors = deque(maxlen=100)
    
    def record_error(self, error_type, context=None):
        """エラーを記録する。"""
        self.error_counts[error_type] += 1
        self.last_errors.append({
            "type": error_type,
            "timestamp": time.time(),
            "context": context or {}
        })
    
    def record_operation(self, operation_type, success):
        """操作の成功/失敗を記録する。"""
        self.error_rates[operation_type].append(0 if success else 1)
        # 直近100件のみ保持
        if len(self.error_rates[operation_type]) > 100:
            self.error_rates[operation_type].pop(0)
    
    def get_error_rate(self, operation_type):
        """操作タイプごとのエラー率を計算する。"""
        records = self.error_rates.get(operation_type, [])
        if not records:
            return 0.0
        return sum(records) / len(records)
    
    def get_most_common_errors(self, limit=10):
        """最も頻繁に発生しているエラータイプを取得する。"""
        return sorted(
            self.error_counts.items(),
            key=lambda x: x[1],
            reverse=True
        )[:limit]
```

### アラート設定

クリティカルなエラーが発生した場合のアラート通知：

```python
def send_alert(error_type, message, severity="warning"):
    """アラートを送信する。"""
    alert_data = {
        "type": error_type,
        "message": message,
        "severity": severity,
        "timestamp": time.time(),
        "environment": ENVIRONMENT
    }
    
    # アラート送信ロジック（例：Slack, メール, PagerDutyなど）
    if severity == "critical":
        # 緊急アラート
        send_pagerduty_alert(alert_data)
        send_slack_alert(alert_data, channel="#alerts-critical")
    elif severity == "warning":
        # 警告アラート
        send_slack_alert(alert_data, channel="#alerts-warnings")
    
    # アラートのログ記録
    logger.warning(f"Alert sent: {error_type} - {message} [{severity}]")
```

## フォールバックメカニズム

サービスの可用性を維持するためのフォールバック戦略：

### グレースフルデグラデーション

```python
def analyze_content_with_fallback(content):
    """コンテンツ分析と段階的なフォールバック。"""
    try:
        # プライマリLLMでの分析試行
        return analyze_with_primary_llm(content)
    except LLMConnectionError:
        # プライマリLLM接続エラー時のフォールバック
        logger.warning("Primary LLM connection failed, falling back to secondary LLM")
        try:
            return analyze_with_secondary_llm(content)
        except LLMConnectionError:
            # セカンダリLLMも失敗した場合、ルールベース処理にフォールバック
            logger.error("Secondary LLM connection failed, falling back to rule-based analysis")
            return analyze_with_rules(content)
    except LLMResponseError:
        # LLMレスポンスエラー時のフォールバック
        logger.warning("LLM returned invalid response, falling back to simplified analysis")
        return analyze_simplified(content)
```

### キャッシュによるフォールバック

```python
def get_analyzed_structure(content_hash):
    """コンテンツ構造を取得し、エラー時にはキャッシュを使用。"""
    try:
        # 最新の分析結果を取得
        return get_fresh_analysis(content_hash)
    except AnalysisError:
        # エラー時にキャッシュから取得
        logger.warning(f"Could not get fresh analysis for {content_hash}, using cached version")
        cached_result = get_cached_analysis(content_hash)
        if cached_result:
            return cached_result
        
        # キャッシュにもない場合は例外を発生
        raise AnalysisNotAvailableError(f"No analysis available for content: {content_hash}")
```

## フェイルファスト原則

早期エラー検出による長時間の無駄な処理の回避：

```python
def process_job(job_data):
    """ジョブを処理し、早期に検証とエラー検出を行う。"""
    # 前提条件の検証
    validation_errors = validate_job_prerequisites(job_data)
    if validation_errors:
        raise ValidationError(f"Job validation failed: {validation_errors}")
    
    # リソース可用性の確認
    if not check_resources_availability():
        raise ResourceUnavailableError("Required resources are not available")
    
    # 依存サービスの健全性チェック
    if not check_dependent_services():
        raise DependencyUnavailableError("One or more required services are unavailable")
    
    # これらの検証をパスした場合のみ、実際の処理を開始
    return process_job_internal(job_data)
```

## エラーハンドリングのベストプラクティス

1. **ドメイン固有の例外を定義する**: 汎用例外ではなく、意味のある例外クラスを使用
2. **必要な情報をエラーに含める**: トラブルシューティングに役立つ詳細情報を提供
3. **適切なレベルで例外を処理する**: 最も適切なレイヤーでエラーを処理
4. **回復可能なエラーには回復戦略を実装する**: 一時的なエラーからの自動回復を検討
5. **詳細なログを残す**: トレースバック情報を含めた詳細なログ記録
6. **ユーザーフレンドリーなエラーメッセージ**: エンドユーザー向けに理解しやすいメッセージを提供
7. **エラーを監視して改善する**: エラー傾向を分析し、根本原因を解決

## 結論

効果的なエラー処理と例外管理は、堅牢で信頼性の高いシステムを構築するための重要な要素です。適切に設計されたエラー処理戦略により、システムは予期しない状況からより早く回復し、ユーザーエクスペリエンスを向上させることができます。
